# HG changeset patch
# User John W. Eaton <jwe@octave.org>
# Date 1484600371 18000
#      Mon Jan 16 15:59:31 2017 -0500
# Branch stable
# Node ID 7f91376af4d3f3e330b5b6457e29d7cb1e131c69
# Parent  7351f2c933895b6363d9cd57b1200db0c4d176ec
don't rethrow exception in destructor (bug #49304)

* ov-oncleanup.cc (octave_oncleanup::~octave_oncleanup):
Don't try to rethrow exception in destructor.  I added incorrectly
added this change to Olaf's patch before pushing it...

diff --git a/libinterp/octave-value/ov-oncleanup.cc b/libinterp/octave-value/ov-oncleanup.cc
--- a/libinterp/octave-value/ov-oncleanup.cc
+++ b/libinterp/octave-value/ov-oncleanup.cc
@@ -93,17 +93,18 @@ octave_oncleanup::~octave_oncleanup (voi
     {
       std::string msg = last_error_message ();
       warning ("onCleanup: error caught while executing cleanup function:\n%s\n",
                msg.c_str ());
 
     }
   catch (const octave::exit_exception&)
     {
-      throw;
+      // This shouldn't happen since we disabled quit above.
+      warning ("onCleanup: exit disabled while executing cleanup function");
     }
   catch (...) // Yes, the black hole.  We're in a d-tor.
     {
       // This shouldn't happen, in theory.
       warning ("onCleanup: internal error: unhandled exception in cleanup action");
     }
 }
 
